Workbook

Sheet SampleInfo
A1: RawSeqID | B1: SampleID | C1: Coverage | D1: Sex | E1: Breed | F1: Registration | G1: SireBreed | H1: SireReg | I1: DamBreed | J1: DamReg | K1: Info
A2: MH_WGS_H1_112 | B2: MH-112 | C2: =SUMIF(QCOverview!$B:$B,B2,QCOverview!$G:$G) -> 25.055914 | D2: M | E2: Angus | F2: NA | G2: Angus | H2: 18205024 | I2: Angus | J2: 19728012 | K2: Maddie's microbiome steers
A3: MH_WGS_E1_1912 | B3: MH-1912 | C3: =SUMIF(QCOverview!$B:$B,B3,QCOverview!$G:$G) -> 21.87533 | D3: M | E3: Angus | F3: NA | G3: Angus | H3: 19573709 | I3: Angus | J3: 17710574 | K3: Maddie's microbiome steers
A4: MH_WGS_D1_192 | B4: MH-192 | C4: =SUMIF(QCOverview!$B:$B,B4,QCOverview!$G:$G) -> 20.236082 | D4: M | E4: Angus | F4: NA | G4: Angus | H4: 19551197 | I4: Angus | J4: 19727953 | K4: Maddie's microbiome steers
A5: MH_WGS_C1_1972 | B5: MH-1972 | C5: =SUMIF(QCOverview!$B:$B,B5,QCOverview!$G:$G) -> 23.404217 | D5: M | E5: Angus | F5: NA | G5: Angus | H5: 19479475 | I5: Angus | J5: 18198705 | K5: Maddie's microbiome steers
A6: WGS1_H2_2392_HennigerSteer3 | B6: MH-2392 | C6: =SUMIF(QCOverview!$B:$B,B6,QCOverview!$G:$G) -> 8.0973336 | D6: M | E6: Angus | F6: NA | G6: Angus | H6: 19526770 | I6: Angus | J6: 18542444 | K6: Maddie's microbiome steers
A7: MH_WGS_A1_2572 | B7: MH-2572 | C7: =SUMIF(QCOverview!$B:$B,B7,QCOverview!$G:$G) -> 25.305518 | D7: M | E7: Angus | F7: NA | G7: Angus | H7: 19573709 | I7: Angus | J7: 18881806 | K7: Maddie's microbiome steers
A8: MH_WGS_G1_3292 | B8: MH-3292 | C8: =SUMIF(QCOverview!$B:$B,B8,QCOverview!$G:$G) -> 21.610656 | D8: M | E8: Angus | F8: NA | G8: Angus | H8: 18881708 | I8: Angus | J8: 19549924 | K8: Maddie's microbiome steers
A9: MH_WGS_F1_3392 | B9: MH-3392 | C9: =SUMIF(QCOverview!$B:$B,B9,QCOverview!$G:$G) -> 21.92697 | D9: M | E9: Angus | F9: NA | G9: Angus | H9: 19815552 | I9: Angus | J9: 18881723 | K9: Maddie's microbiome steers
A10: MH_WGS_B1_472 | B10: MH-472 | C10: =SUMIF(QCOverview!$B:$B,B10,QCOverview!$G:$G) -> 23.406278 | D10: M | E10: Angus | F10: NA | G10: Angus | H10: 19815550 | I10: Angus | J10: 19728412 | K10: Maddie's microbiome steers
A11: RowanHet_Angus_7777 | B11: ROW-7777 | C11: =SUMIF(QCOverview!$B:$B,B11,QCOverview!$G:$G) -> 12.6316 | D11: F | E11: Angus | K11: Troy's heterosis cattle
A12: RowanHet_Angus_7785 | B12: ROW-7785 | C12: =SUMIF(QCOverview!$B:$B,B12,QCOverview!$G:$G) -> 10.348 | D12: F | E12: Angus | K12: Troy's heterosis cattle
A13: RowanHet_Angus_7792 | B13: ROW-7792 | C13: =SUMIF(QCOverview!$B:$B,B13,QCOverview!$G:$G) -> 14.155778 | D13: F | E13: Angus | K13: Troy's heterosis cattle
A14: RowanHet_Angus_7797 | B14: ROW-7797 | C14: =SUMIF(QCOverview!$B:$B,B14,QCOverview!$G:$G) -> 11.134474 | D14: F | E14: Angus | K14: Troy's heterosis cattle
A15: RowanHet_Angus_7798 | B15: ROW-7798 | C15: =SUMIF(QCOverview!$B:$B,B15,QCOverview!$G:$G) -> 11.535693 | D15: F | E15: Angus | K15: Troy's heterosis cattle
A16: RowanHet_Angus_7799_Beever240927 | B16: ROW-7799 | C16: =SUMIF(QCOverview!$B:$B,B16,QCOverview!$G:$G) -> 16.443176 | D16: F | E16: Angus | K16: Troy's heterosis cattle
A17: RowanHet_Angus_7800 | B17: ROW-7800 | C17: =SUMIF(QCOverview!$B:$B,B17,QCOverview!$G:$G) -> 11.86988 | D17: F | E17: Angus | K17: Troy's heterosis cattle
A18: WGS2_E9_7852_RowanBrahCow | B18: ROW-7852 | C18: =SUMIF(QCOverview!$B:$B,B18,QCOverview!$G:$G) -> 9.8636359 | D18: F | E18: Brahman | K18: Troy's heterosis cattle
A19: WGS2_F9_7854_RowanBrahCow | B19: ROW-7854 | C19: =SUMIF(QCOverview!$B:$B,B19,QCOverview!$G:$G) -> 13.859262 | D19: F | E19: Brahman | K19: Troy's heterosis cattle
A20: WGS2_G9_7855_RowanBrahCow | B20: ROW-7855 | C20: =SUMIF(QCOverview!$B:$B,B20,QCOverview!$G:$G) -> 14.658148 | D20: F | E20: Brahman | K20: Troy's heterosis cattle
A21: WGS2_H9_7856_RowanBrahCow | B21: ROW-7856 | C21: =SUMIF(QCOverview!$B:$B,B21,QCOverview!$G:$G) -> 11.63953 | D21: F | E21: Brahman | K21: Troy's heterosis cattle
A22: WGS2_A10_7857_RowanBrahCow | B22: ROW-7857 | C22: =SUMIF(QCOverview!$B:$B,B22,QCOverview!$G:$G) -> 10.668061 | D22: F | E22: Brahman | K22: Troy's heterosis cattle
... A61: WGS2_B9_TM_RowanHetSemen_2024 | B61: ROW-BullTM | C61: =SUMIF(QCOverview!$B:$B,B61,QCOverview!$G:$G) -> 30.61111 | D61: M | E61: Brahman? | K61: TetonManso?
A62: WGS2_A1_230929 | B62: UIUC-145A | C62: =SUMIF(QCOverview!$B:$B,B62,QCOverview!$G:$G) -> 14.000845 | D62: F | E62: Charolais | F62: NA | G62: Charolais | H62: M606732 | I62: Simmental | J62: 9723316 | K62: qq.1
A63: WGSBeever_175A_A1 | B63: UIUC-175A | C63: =SUMIF(QCOverview!$B:$B,B63,QCOverview!$G:$G) -> 19.31161 | D63: M | E63: Charolais | F63: NA | G63: Charolais | H63: M669488 | I63: Simmental | J63: 9695103 | K63: qq.7
A64: WGS2_B1_230929 | B64: UIUC-177A | C64: =SUMIF(QCOverview!$B:$B,B64,QCOverview!$G:$G) -> 11.641192 | D64: M | E64: Charolais | F64: NA | G64: Charolais | H64: EM777360 | I64: Simmental | J64: 9581645 | K64: QQ.7
A65: WGS2_C1_230929 | B65: UIUC-234A | C65: =SUMIF(QCOverview!$B:$B,B65,QCOverview!$G:$G) -> 15.715586 | D65: M | E65: Charolais | F65: NA | G65: Charolais | H65: M470827 | I65: Simmental | J65: 8873419 | K65: qq.16
A66: WGS2_D1_230929 | B66: UIUC-238A | C66: =SUMIF(QCOverview!$B:$B,B66,QCOverview!$G:$G) -> 16.23949 | D66: F | E66: Charolais | F66: NA | G66: Charolais | H66: M669488 | I66: Simmental | J66: 9723438 | K66: qq.2
A67: WGS2_E1_230929 | B67: UIUC-243A | C67: =SUMIF(QCOverview!$B:$B,B67,QCOverview!$G:$G) -> 15.071078 | D67: M | E67: Charolais | F67: NA | G67: Charolais | H67: M669488 | I67: Simmental | J67: 9723226 | K67: qq.8
A68: WGS2_F1_230929 | B68: UIUC-267A | C68: =SUMIF(QCOverview!$B:$B,B68,QCOverview!$G:$G) -> 13.475672 | D68: F | E68: Charolais | F68: NA | G68: Charolais | H68: M669488 | I68: Simmental | J68: 9581602 | K68: qq.3
A69: WGS2_G1_230929 | B69: UIUC-268A | C69: =SUMIF(QCOverview!$B:$B,B69,QCOverview!$G:$G) -> 14.590001 | D69: F | E69: Charolais | F69: NA | G69: Charolais | H69: M726505 | I69: Simmental | J69: 9134957 | K69: QQ.1
A70: WGS2_H1_230929 | B70: UIUC-283A | C70: =SUMIF(QCOverview!$B:$B,B70,QCOverview!$G:$G) -> 12.95679 | D70: F | E70: Charolais | F70: NA | G70: Charolais | H70: M508800 | I70: Simmental | J70: 9583157 | K70: QQ.2
A71: WGS2_A2_230929 | B71: UIUC-322A | C71: =SUMIF(QCOverview!$B:$B,B71,QCOverview!$G:$G) -> 13.044015 | D71: M | E71: Charolais | F71: NA | G71: Charolais | H71: M736773 | I71: Simmental | J71: 9583112 | K71: QQ.8
A72: WGS2_B2_230929 | B72: UIUC-323A | C72: =SUMIF(QCOverview!$B:$B,B72,QCOverview!$G:$G) -> 12.991626 | D72: M | E72: Charolais | F72: NA | G72: Charolais | H72: M606732 | I72: Simmental | J72: 9562559 | K72: qq.17
A73: WGS2_C2_230929 | B73: UIUC-329A | C73: =SUMIF(QCOverview!$B:$B,B73,QCOverview!$G:$G) -> 12.474839 | D73: M | E73: Charolais | F73: NA | G73: Charolais | H73: M508800 | I73: Simmental | J73: 9581523 | K73: QQ.9
... A88: WGS2_B4_230929 | B88: UIUC-482A | C88: =SUMIF(QCOverview!$B:$B,B88,QCOverview!$G:$G) -> 14.568875 | D88: F | E88: Charolais | F88: NA | G88: Charolais | H88: M606732 | I88: Simmental | J88: 9583132 | K88: qq.6
A89: WGSBeever_UI3061_B1 | B89: UIUC-485A | C89: =SUMIF(QCOverview!$B:$B,B89,QCOverview!$G:$G) -> 19.479863 | D89: F | E89: Charolais | F89: NA | G89: NA | H89: NA | I89: NA | J89: NA | K89: QQ.4
A90: WGS2_C4_230929 | B90: UIUC-487A | C90: =SUMIF(QCOverview!$B:$B,B90,QCOverview!$G:$G) -> 14.593596 | D90: M | E90: Charolais | F90: NA | G90: Charolais | H90: M745957 | I90: Simmental | J90: 9695018 | K90: QQ.18
A91: WGS2_D4_230929 | B91: UIUC-502A | C91: =SUMIF(QCOverview!$B:$B,B91,QCOverview!$G:$G) -> 16.479188 | D91: M | E91: Charolais | F91: NA | G91: Charolais | H91: M773446 | I91: Simmental | J91: 9637906 | K91: QQ.12
A92: WGS2_E4_230929 | B92: UIUC-522A | C92: =SUMIF(QCOverview!$B:$B,B92,QCOverview!$G:$G) -> 12.735641 | D92: F | E92: Charolais | F92: NA | G92: Charolais | H92: M773446 | I92: Simmental | J92: 9053132 | K92: QQ.5
...

Sheet QCOverview
A1: RawSeqID | B1: SampleID | C1: SeqGroup | D1: Info | E1: QC Fail? | F1: TotalRawSeqs | G1: MaxPosCoverage
A2: Brink_A3_230828 | B2: Brink-H041 | C2: 230828_Mix1 | D2: brachygnathia | F2: =SUMIF(raw_seqs!$B:$B, A2, raw_seqs!$C:$C)+SUMIF(raw_seqs!$B:$B, A2, raw_seqs!$D:$D) -> 232612734 | G2: =(F2*150)/2700000000 -> 12.92293
A3: Brink_B3_230828 | B3: Brink-J1035 | C3: 230828_Mix1 | D3: brachygnathia | F3: =SUMIF(raw_seqs!$B:$B, A3, raw_seqs!$C:$C)+SUMIF(raw_seqs!$B:$B, A3, raw_seqs!$D:$D) -> 226646810 | G3: =(F3*150)/2700000000 -> 12.591489
A4: Brink_C3_230828 | B4: Brink-J1041 | C4: 230828_Mix1 | D4: brachygnathia | F4: =SUMIF(raw_seqs!$B:$B, A4, raw_seqs!$C:$C)+SUMIF(raw_seqs!$B:$B, A4, raw_seqs!$D:$D) -> 221512420 | G4: =(F4*150)/2700000000 -> 12.306246
A5: Brink_D3_230828 | B5: Brink-J1052 | C5: 230828_Mix1 | D5: brachygnathia | F5: =SUMIF(raw_seqs!$B:$B, A5, raw_seqs!$C:$C)+SUMIF(raw_seqs!$B:$B, A5, raw_seqs!$D:$D) -> 204350992 | G5: =(F5*150)/2700000000 -> 11.352833
A6: Brink_E3_230828 | B6: Brink-Z204 | C6: 230828_Mix1 | D6: brachygnathia | F6: =SUMIF(raw_seqs!$B:$B, A6, raw_seqs!$C:$C)+SUMIF(raw_seqs!$B:$B, A6, raw_seqs!$D:$D) -> 188606464 | G6: =(F6*150)/2700000000 -> 10.478137
A7: Brink_F3_230828 | B7: Brink-calf1 | C7: 230828_Mix1 | D7: brachygnathia | F7: =SUMIF(raw_seqs!$B:$B, A7, raw_seqs!$C:$C)+SUMIF(raw_seqs!$B:$B, A7, raw_seqs!$D:$D) -> 177169780 | G7: =(F7*150)/2700000000 -> 9.8427656
A8: Brink_G3_230828 | B8: Brink-calf2 | C8: 230828_Mix1 | D8: brachygnathia | F8: =SUMIF(raw_seqs!$B:$B, A8, raw_seqs!$C:$C)+SUMIF(raw_seqs!$B:$B, A8, raw_seqs!$D:$D) -> 235744656 | G8: =(F8*150)/2700000000 -> 13.096925
A9: Brink_H3_230828 | B9: Brink-calf3 | C9: 230828_Mix1 | D9: brachygnathia | F9: =SUMIF(raw_seqs!$B:$B, A9, raw_seqs!$C:$C)+SUMIF(raw_seqs!$B:$B, A9, raw_seqs!$D:$D) -> 248576000 | G9: =(F9*150)/2700000000 -> 13.809778
A10: MixWGS1_1A10_230828 | B10: ASA-2474338 | C10: 230828_Mix1 | D10: ASA bull | F10: =SUMIF(raw_seqs!$B:$B, A10, raw_seqs!$C:$C)+SUMIF(raw_seqs!$B:$B, A10, raw_seqs!$D:$D) -> 462470634 | G10: =(F10*150)/2700000000 -> 25.692813
A11: MixWGS1_1A11_230828 | B11: ASA-2559346 | C11: 230828_Mix1 | D11: ASA bull | F11: =SUMIF(raw_seqs!$B:$B, A11, raw_seqs!$C:$C)+SUMIF(raw_seqs!$B:$B, A11, raw_seqs!$D:$D) -> 166919554 | G11: =(F11*150)/2700000000 -> 9.2733086
A12: MixWGS1_1A12_230828 | B12: ASA-2720494 | C12: 230828_Mix1 | D12: ASA bull | F12: =SUMIF(raw_seqs!$B:$B, A12, raw_seqs!$C:$C)+SUMIF(raw_seqs!$B:$B, A12, raw_seqs!$D:$D) -> 233678094 | G12: =(F12*150)/2700000000 -> 12.982116
A13: MixWGS1_1A4_230828 | B13: UTIA-0110 | C13: 230828_Mix1 | D13: eye pigmentation | F13: =SUMIF(raw_seqs!$B:$B, A13, raw_seqs!$C:$C)+SUMIF(raw_seqs!$B:$B, A13, raw_seqs!$D:$D) -> 174946264 | G13: =(F13*150)/2700000000 -> 9.7192369
... A29: MixWGS1_1C9_230828 | B29: ASA-2180592 | C29: 230828_Mix1 | D29: ASA bull | F29: =SUMIF(raw_seqs!$B:$B, A29, raw_seqs!$C:$C)+SUMIF(raw_seqs!$B:$B, A29, raw_seqs!$D:$D) -> 194190850 | G29: =(F29*150)/2700000000 -> 10.788381
A30: MixWGS1_1D10_230828 | B30: ASA-2728015 | C30: 230828_Mix1 | D30: ASA bull | E30: GC Content | F30: =SUMIF(raw_seqs!$B:$B, A30, raw_seqs!$C:$C)+SUMIF(raw_seqs!$B:$B, A30, raw_seqs!$D:$D) -> 190901458 | G30: =(F30*150)/2700000000 -> 10.605637
A31: MixWGS1_1D11_230828 | B31: ASA-2409687 | C31: 230828_Mix1 | D31: ASA bull | F31: =SUMIF(raw_seqs!$B:$B, A31, raw_seqs!$C:$C)+SUMIF(raw_seqs!$B:$B, A31, raw_seqs!$D:$D) -> 260093970 | G31: =(F31*150)/2700000000 -> 14.449665
A32: MixWGS1_1D12_230828 | B32: ASA-2757819 | C32: 230828_Mix1 | D32: ASA bull | F32: =SUMIF(raw_seqs!$B:$B, A32, raw_seqs!$C:$C)+SUMIF(raw_seqs!$B:$B, A32, raw_seqs!$D:$D) -> 198783256 | G32: =(F32*150)/2700000000 -> 11.043514
A33: MixWGS1_1D2_230828 | B33: UTIA-0222 | C33: 230828_Mix1 | D33: cancer eye | F33: =SUMIF(raw_seqs!$B:$B, A33, raw_seqs!$C:$C)+SUMIF(raw_seqs!$B:$B, A33, raw_seqs!$D:$D) -> 256598092 | G33: =(F33*150)/2700000000 -> 14.25545
A34: MixWGS1_1D4_230828 | B34: UTIA-0113 | C34: 230828_Mix1 | D34: eye pigmentation | F34: =SUMIF(raw_seqs!$B:$B, A34, raw_seqs!$C:$C)+SUMIF(raw_seqs!$B:$B, A34, raw_seqs!$D:$D) -> 255109018 | G34: =(F34*150)/2700000000 -> 14.172723
A35: MixWGS1_1D5_230828 | B35: UTIA-0156 | C35: 230828_Mix1 | D35: hypotrichosis | F35: =SUMIF(raw_seqs!$B:$B, A35, raw_seqs!$C:$C)+SUMIF(raw_seqs!$B:$B, A35, raw_seqs!$D:$D) -> 188073344 | G35: =(F35*150)/2700000000 -> 10.448519
A36: MixWGS1_1D6_230828 | B36: UTIA-0151 | C36: 230828_Mix1 | D36: cryptorchidism | F36: =SUMIF(raw_seqs!$B:$B, A36, raw_seqs!$C:$C)+SUMIF(raw_seqs!$B:$B, A36, raw_seqs!$D:$D) -> 258318032 | G36: =(F36*150)/2700000000 -> 14.351002
A37: MixWGS1_1D8_230828 | B37: ASA-2224042 | C37: 230828_Mix1 | D37: ASA bull | F37: =SUMIF(raw_seqs!$B:$B, A37, raw_seqs!$C:$C)+SUMIF(raw_seqs!$B:$B, A37, raw_seqs!$D:$D) -> 187952516 | G37: =(F37*150)/2700000000 -> 10.441806
A38: MixWGS1_1D9_230828 | B38: ASA-2588250 | C38: 230828_Mix1 | D38: ASA bull | F38: =SUMIF(raw_seqs!$B:$B, A38, raw_seqs!$C:$C)+SUMIF(raw_seqs!$B:$B, A38, raw_seqs!$D:$D) -> 220120000 | G38: =(F38*150)/2700000000 -> 12.228889
A39: MixWGS1_1E10_230828 | B39: ASA-2725666 | C39: 230828_Mix1 | D39: ASA bull | F39: =SUMIF(raw_seqs!$B:$B, A39, raw_seqs!$C:$C)+SUMIF(raw_seqs!$B:$B, A39, raw_seqs!$D:$D) -> 170920382 | G39: =(F39*150)/2700000000 -> 9.4955768
A40: MixWGS1_1E11_230828 | B40: ASA-2531081 | C40: 230828_Mix1 | D40: ASA bull | F40: =SUMIF(raw_seqs!$B:$B, A40, raw_seqs!$C:$C)+SUMIF(raw_seqs!$B:$B, A40, raw_seqs!$D:$D) -> 151664104 | G40: =(F40*150)/2700000000 -> 8.4257836
A41: MixWGS1_1E12_230828 | B41: ASA-2646300 | C41: 230828_Mix1 | D41: ASA bull | F41: =SUMIF(raw_seqs!$B:$B, A41, raw_seqs!$C:$C)+SUMIF(raw_seqs!$B:$B, A41, raw_seqs!$D:$D) -> 184974978 | G41: =(F41*150)/2700000000 -> 10.276388
A42: MixWGS1_1E2_230828 | B42: UTIA-0223 | C42: 230828_Mix1 | D42: cancer eye | F42: =SUMIF(raw_seqs!$B:$B, A42, raw_seqs!$C:$C)+SUMIF(raw_seqs!$B:$B, A42, raw_seqs!$D:$D) -> 205781872 | G42: =(F42*150)/2700000000 -> 11.432326
... A107: WGS2_H4_230929 | B107: UIUC-536A | C107: 230929_Charolais | D107: QQ.6 | F107: =SUMIF(raw_seqs!$B:$B, A107, raw_seqs!$C:$C)+SUMIF(raw_seqs!$B:$B, A107, raw_seqs!$D:$D) -> 196728374 | G107: =(F107*150)/2700000000 -> 10.929354
A108: WGS3_A1_570_HennigerSteer5_2024 | C108: 240212_AngusSteers1 | E108: Insufficient Coverage | F108: =SUMIF(raw_seqs!$B:$B, A108, raw_seqs!$C:$C)+SUMIF(raw_seqs!$B:$B, A108, raw_seqs!$D:$D) -> 34614160 | G108: =(F108*150)/2700000000 -> 1.9230089
A109: WGS3_A10_2710_HennigerSteer5_2024 | C109: 240212_AngusSteers1 | E109: Insufficient Coverage | F109: =SUMIF(raw_seqs!$B:$B, A109, raw_seqs!$C:$C)+SUMIF(raw_seqs!$B:$B, A109, raw_seqs!$D:$D) -> 29887684 | G109: =(F109*150)/2700000000 -> 1.6604269
A110: WGS3_A11_1850_HennigerSteer5_2024 | C110: 240212_AngusSteers1 | E110: Insufficient Coverage | F110: =SUMIF(raw_seqs!$B:$B, A110, raw_seqs!$C:$C)+SUMIF(raw_seqs!$B:$B, A110, raw_seqs!$D:$D) -> 31408496 | G110: =(F110*150)/2700000000 -> 1.7449164
A111: WGS3_A12_1430_HennigerSteer5_2024 | C111: 240212_AngusSteers1 | E111: Insufficient Coverage | F111: =SUMIF(raw_seqs!$B:$B, A111, raw_seqs!$C:$C)+SUMIF(raw_seqs!$B:$B, A111, raw_seqs!$D:$D) -> 33743260 | G111: =(F111*150)/2700000000 -> 1.8746256
A112: WGS3_A2_1910_HennigerSteer5_2024 | C112: 240212_AngusSteers1 | E112: Insufficient Coverage | F112: =SUMIF(raw_seqs!$B:$B, A112, raw_seqs!$C:$C)+SUMIF(raw_seqs!$B:$B, A112, raw_seqs!$D:$D) -> 31909940 | G112: =(F112*150)/2700000000 -> 1.7727744
A113: WGS3_A3_2810_HennigerSteer5_2024 | C113: 240212_AngusSteers1 | E113: Insufficient Coverage | F113: =SUMIF(raw_seqs!$B:$B, A113, raw_seqs!$C:$C)+SUMIF(raw_seqs!$B:$B, A113, raw_seqs!$D:$D) -> 35086524 | G113: =(F113*150)/2700000000 -> 1.9492513
A114: WGS3_A4_1750_HennigerSteer5_2024 | C114: 240212_AngusSteers1 | E114: Insufficient Coverage | F114: =SUMIF(raw_seqs!$B:$B, A114, raw_seqs!$C:$C)+SUMIF(raw_seqs!$B:$B, A114, raw_seqs!$D:$D) -> 28165920 | G114: =(F114*150)/2700000000 -> 1.5647733
A115: WGS3_A5_3_HennigerSteer5_2024 | C115: 240212_AngusSteers1 | E115: Insufficient Coverage | F115: =SUMIF(raw_seqs!$B:$B, A115, raw_seqs!$C:$C)+SUMIF(raw_seqs!$B:$B, A115, raw_seqs!$D:$D) -> 32953602 | G115: =(F115*150)/2700000000 -> 1.8307557
A116: WGS3_A6_1310_HennigerSteer5_2024 | C116: 240212_AngusSteers1 | E116: Insufficient Coverage | F116: =SUMIF(raw_seqs!$B:$B, A116, raw_seqs!$C:$C)+SUMIF(raw_seqs!$B:$B, A116, raw_seqs!$D:$D) -> 38220794 | G116: =(F116*150)/2700000000 -> 2.1233774
A117: WGS3_A7_1890_HennigerSteer5_2024 | C117: 240212_AngusSteers1 | E117: Insufficient Coverage | F117: =SUMIF(raw_seqs!$B:$B, A117, raw_seqs!$C:$C)+SUMIF(raw_seqs!$B:$B, A117, raw_seqs!$D:$D) -> 36693650 | G117: =(F117*150)/2700000000 -> 2.0385361
A118: WGS3_A8_2150_HennigerSteer5_2024 | C118: 240212_AngusSteers1 | E118: Insufficient Coverage | F118: =SUMIF(raw_seqs!$B:$B, A118, raw_seqs!$C:$C)+SUMIF(raw_seqs!$B:$B, A118, raw_seqs!$D:$D) -> 29364044 | G118: =(F118*150)/2700000000 -> 1.6313358
A119: WGS3_A9_2550_HennigerSteer5_2024 | C119: 240212_AngusSteers1 | E119: Insufficient Coverage | F119: =SUMIF(raw_seqs!$B:$B, A119, raw_seqs!$C:$C)+SUMIF(raw_seqs!$B:$B, A119, raw_seqs!$D:$D) -> 25331228 | G119: =(F119*150)/2700000000 -> 1.4072904
...

Sheet raw_seqs
A1: Sample | B1: Sample | C1: Unique Reads | D1: Duplicate Reads
A2: Brink_A3_230828_S96_L001_R1_001 | B2: Brink_A3_230828 | C2: 22530653 | D2: 7111639
A3: Brink_A3_230828_S96_L001_R2_001 | B3: Brink_A3_230828 | C3: 23021230 | D3: 6621062
A4: Brink_A3_230828_S96_L002_R1_001 | B4: Brink_A3_230828 | C4: 23847631 | D4: 6167216
A5: Brink_A3_230828_S96_L002_R2_001 | B5: Brink_A3_230828 | C5: 24294657 | D5: 5720190
A6: Brink_A3_230828_S96_L003_R1_001 | B6: Brink_A3_230828 | C6: 22905974 | D6: 5583125
A7: Brink_A3_230828_S96_L003_R2_001 | B7: Brink_A3_230828 | C7: 23292063 | D7: 5197036
A8: Brink_A3_230828_S96_L004_R1_001 | B8: Brink_A3_230828 | C8: 22808170 | D8: 5351959
A9: Brink_A3_230828_S96_L004_R2_001 | B9: Brink_A3_230828 | C9: 23108995 | D9: 5051134
A10: Brink_B3_230828_S97_L001_R1_001 | B10: Brink_B3_230828 | C10: 22428577 | D10: 6172957
A11: Brink_B3_230828_S97_L001_R2_001 | B11: Brink_B3_230828 | C11: 22701418 | D11: 5900116
A12: Brink_B3_230828_S97_L002_R1_001 | B12: Brink_B3_230828 | C12: 23353361 | D12: 5102716
A13: Brink_B3_230828_S97_L002_R2_001 | B13: Brink_B3_230828 | C13: 23615190 | D13: 4840887
... A577: MixWGS1_2B12_230828_S89_L004_R2_001 | B577: MixWGS1_2B12_230828 | C577: 27262747 | D577: 6211860
A578: Sample | B578: Sample | C578: Unique Reads | D578: Duplicate Reads
A579: WGS2_A1_230929_S1_L001_R1_001 | B579: WGS2_A1_230929 | C579: 48541838 | D579: 15191749
A580: WGS2_A1_230929_S1_L001_R2_001 | B580: WGS2_A1_230929 | C580: 49162376 | D580: 14571211
A581: WGS2_A1_230929_S1_L002_R1_001 | B581: WGS2_A1_230929 | C581: 47695848 | D581: 14578167
A582: WGS2_A1_230929_S1_L002_R2_001 | B582: WGS2_A1_230929 | C582: 48288781 | D582: 13985234
A583: WGS2_A2_230929_S9_L001_R1_001 | B583: WGS2_A2_230929 | C583: 45090200 | D583: 14227017
A584: WGS2_A2_230929_S9_L001_R2_001 | B584: WGS2_A2_230929 | C584: 45613649 | D584: 13703568
A585: WGS2_A2_230929_S9_L002_R1_001 | B585: WGS2_A2_230929 | C585: 44311189 | D585: 13767733
A586: WGS2_A2_230929_S9_L002_R2_001 | B586: WGS2_A2_230929 | C586: 44925739 | D586: 13153183
A587: WGS2_A3_230929_S17_L001_R1_001 | B587: WGS2_A3_230929 | C587: 45325681 | D587: 14439125
A588: WGS2_A3_230929_S17_L001_R2_001 | B588: WGS2_A3_230929 | C588: 45799302 | D588: 13965504
A589: WGS2_A3_230929_S17_L002_R1_001 | B589: WGS2_A3_230929 | C589: 44657786 | D589: 14059869
A590: WGS2_A3_230929_S17_L002_R2_001 | B590: WGS2_A3_230929 | C590: 45207459 | D590: 13510196
... A714: WGS2_H4_230929_S32_L002_R2_001 | B714: WGS2_H4_230929 | C714: 37991585 | D714: 10624501
A715: Sample | B715: Sample | C715: Unique Reads | D715: Duplicate Reads
A716: WGS3_A10_2710_HennigerSteer5_2024_S209_L003_R1_001 | B716: WGS3_A10_2710_HennigerSteer5_2024 | C716: 10075952 | D716: 4867890
A717: WGS3_A10_2710_HennigerSteer5_2024_S209_L003_R2_001 | B717: WGS3_A10_2710_HennigerSteer5_2024 | C717: 10188480 | D717: 4755362
A718: WGS3_A11_1850_HennigerSteer5_2024_S217_L003_R1_001 | B718: WGS3_A11_1850_HennigerSteer5_2024 | C718: 10320627 | D718: 5383621
A719: WGS3_A11_1850_HennigerSteer5_2024_S217_L003_R2_001 | B719: WGS3_A11_1850_HennigerSteer5_2024 | C719: 10457799 | D719: 5246449
A720: WGS3_A12_1430_HennigerSteer5_2024_S225_L003_R1_001 | B720: WGS3_A12_1430_HennigerSteer5_2024 | C720: 11066875 | D720: 5804755
A721: WGS3_A12_1430_HennigerSteer5_2024_S225_L003_R2_001 | B721: WGS3_A12_1430_HennigerSteer5_2024 | C721: 11180770 | D721: 5690860
A722: WGS3_A1_570_HennigerSteer5_2024_S137_L003_R1_001 | B722: WGS3_A1_570_HennigerSteer5_2024 | C722: 11332883 | D722: 5974197
A723: WGS3_A1_570_HennigerSteer5_2024_S137_L003_R2_001 | B723: WGS3_A1_570_HennigerSteer5_2024 | C723: 11531455 | D723: 5775625
A724: WGS3_A2_1910_HennigerSteer5_2024_S145_L003_R1_001 | B724: WGS3_A2_1910_HennigerSteer5_2024 | C724: 10792585 | D724: 5162385
A725: WGS3_A2_1910_HennigerSteer5_2024_S145_L003_R2_001 | B725: WGS3_A2_1910_HennigerSteer5_2024 | C725: 10884557 | D725: 5070413
A726: WGS3_A3_2810_HennigerSteer5_2024_S153_L003_R1_001 | B726: WGS3_A3_2810_HennigerSteer5_2024 | C726: 11281926 | D726: 6261336
...

Sheet UTKGenomicsCore Directories
A1: Directory in UTKGenomicsCore/ | B1: What's in it | C1: Use?
A2: 240214_A01770_0066_BH3TTWDSXC | B2: A mix of some RNA-seq projects | C2: No
A3: 240702_A01770_0074_BHWGGJDMXY | B3: ???? Looks like something went wrong | C3: No
A4: 20240724_FS10003266_1_BTR99609-2438 | B4: Some test sequencing by the looks of it | C4: No
A5: 221010_A01770_0017_BHMGW7DRX2 | B5: Renwick's RNA samples. Had some issues, don't remember much else. | C5: No
A6: 221108_A01770_0018_AHF3HVDMXY | B6: My first RNAseq run. Very high levels of rRNA sequence. | C6: No
A7: 230120_A01770_0024_BHVMNKDRX2 | B7: One of Troy's heterosis RNAseq projects. Looks like it has some trim stuff in it for some reason?????? | C7: No
A8: 230207_A01770_0027_BHJ7NNDMXY | B8: Same as 230120 | C8: No
A9: 230215_A01770_0028_AHWKTGDRX2 | B9: Rius & someone else's RNAseq data. Also has the trim thing. | C9: No
A10: 230310_A01770_0030_AHY2L3DRX2 | B10: Takara RNAseq for Rius and same other person, also has trim thing. | C10: No
A11: 230320_A01770_0031_BH2GMMDRX3 | B11: Renwick Takara RNA-seq | C11: No
A12: 230609_A01770_0038_BHKVCHDMXY | B12: Yadav ASNLT, I don't know what this is | C12: No
... A32: 250331_A01770_0099_BHC273DSXF | B32: even more horses | C32: No
A33: 230828_A01770_0046_BHCLVKDSX7 | B33: MixWGS, includes some cattle | C33: Yes | D33: Mix1; herefords and simmentals mostly
A34: 230929_A01770_0058_BHMTN3DMXY | B34: My Charolais | C34: Yes | D34: Charolais
A35: 240212_A01770_0065_AH2J2JDSXC | B35: WGS (Troy Semen and Maddie's Steers; should be usable?) | C35: Yes | D35: HetBulls & AngusSteers1
A36: 240429_A01770_0071_BH3TCYDSXC | B36: Maddie's Steers | C36: Yes | D36: AngusSteers2
A37: 240501_A01770_0072_AHH5VKDSXC | B37: My K's and Shorthorns, also 6 of Troy's Brahman cows | C37: Yes | D37: KSH & BrahCows1
A38: 240712_A01770_0075_BHKJJFDSXC | B38: 28 of Troy's Brahman cows | C38: Yes | D38: BrahCows2
A39: 240725_A01770_0076_BHL32YDSXC | B39: Brahman and Angus Cows, also a mix of Simmentals, dermoids, and cancer eye samples | C39: Yes | D39: BrahAngCows, SimBulls, & Herf3
A40: 240927_A01770_0081_BHKGH5DRX5 | B40: A few random cattle | C40: Yes | D40: Mix2; ASA, herfs, dermoids, angus & brahman
A41: 241210_VL00838_11_AAGGVKLM5 | B41: Some of Erin's Wagyu | C41: Yes | D41: Wagyu1
A42: 250131_A01770_0094_BHT22JDSXC | B42: Some Wagyu, random cattle including 2 of my Charolais | C42: Yes | D42: Wagyu2 & Mix3
A43: 250514_A01770_0103_BH7YYYDSXF | B43: Erin's Wagyu and also some WGS of Maddie's | C43: Yes | D43: Wagyu3 & MH
